{"name": "test_print15", "status": "failed", "statusDetails": {"message": "AssertionError: assert '1 function' in '2 function call'", "trace": "def test_print15():\n        flag = '2 function call'\n        printknow1()\n        printknow3()\n>       assert '1 function' in flag\nE       AssertionError: assert '1 function' in '2 function call'\n\napiauto\\test_doit5.py:30: AssertionError"}, "start": 1684305735900, "stop": 1684305735900, "uuid": "6a7cd63f-5fd2-4c0b-b27a-1ab1d5f3ffa0", "historyId": "004f2fb62e99c49c3bb45e229dfbc5b0", "testCaseId": "8eab7231fbfecee1cbcaaa83ca35650c", "fullName": "apiauto.test_doit5#test_print15", "labels": [{"name": "parentSuite", "value": "apiauto"}, {"name": "suite", "value": "test_doit5"}, {"name": "host", "value": "DESKTOP-S1E0NQI"}, {"name": "thread", "value": "11072-MainThread"}, {"name": "framework", "value": "pytest"}, {"name": "language", "value": "cpython3"}, {"name": "package", "value": "apiauto.test_doit5"}]}